#VRML_SIM R2020a utf8
WorldInfo {
  basicTimeStep 16
}
Viewpoint {
  orientation 0.9587750401848322 -0.1802406814917565 -0.2196900522416998 5.947505356541105
  position 0.014706223486982008 0.46258076622184496 0.9629165048498484
}
TexturedBackground {
}
TexturedBackgroundLight {
}
Floor {
  size 1 1
}
WoodenBox {
  translation 0.143616 0.05 -0.278754
  rotation 0 -1 0 0.287979
  name "wooden box(2)"
  size 0.1 0.1 0.1
}
WoodenBox {
  translation -0.25093 0.05 0.278239
  name "wooden box(3)"
  size 0.1 0.1 0.1
}
WoodenBox {
  translation 0.18736 0.05 0.212998
  rotation 0 1 0 1.37008
  name "wooden box(1)"
  size 0.1 0.1 0.1
}
Solid {
  translation -0.495274 0.025 0.00388046
  children [
    DEF PAREDE Shape {
      appearance PBRAppearance {
        baseColor 0 0.0666667 1
        roughness 0.5
        metalness 0
      }
      geometry Box {
        size 0.01 0.05 0.98
      }
    }
  ]
  name "solid(3)"
  boundingObject USE PAREDE
}
Solid {
  translation -0.00122568 0.025 -0.495482
  rotation 0 1 0 1.57596
  children [
    Shape {
      appearance PBRAppearance {
        baseColor 0 0.0666667 1
        roughness 0.5
        metalness 0
      }
      geometry Box {
        size 0.01 0.05 0.98
      }
    }
    USE PAREDE
  ]
  name "solid(6)"
  boundingObject USE PAREDE
}
Solid {
  translation 0.494371 0.025 -0.00326243
  children [
    Shape {
      appearance PBRAppearance {
        baseColor 0 0.0666667 1
        roughness 0.5
        metalness 0
      }
      geometry Box {
        size 0.01 0.05 0.98
      }
    }
    USE PAREDE
  ]
  name "solid(4)"
  boundingObject USE PAREDE
}
Solid {
  translation -0.00139261 0.025 0.491632
  rotation 0 1 0 1.5708
  children [
    Shape {
      appearance PBRAppearance {
        baseColor 0 0.0666667 1
        roughness 0.5
        metalness 0
      }
      geometry Box {
        size 0.01 0.05 0.98
      }
    }
    USE PAREDE
  ]
  name "solid(5)"
  boundingObject USE PAREDE
}
Robot {
  translation -0.021213 0.04 -0.0519406
  rotation 0 1 0 0.0698132
  children [
    DistanceSensor {
      translation 0.02 0 0.1
      rotation 0 1 0 -1.1780996938995747
      children [
        Shape {
          appearance PBRAppearance {
            baseColor 0 0.333333 1
            roughness 0.5
            metalness 0
          }
          geometry Box {
            size 0.01 0.01 0.01
          }
        }
      ]
      name "ds_left"
    }
    DistanceSensor {
      translation -0.02 0 0.1
      rotation 0 1 0 -2.0944003061004253
      children [
        Shape {
          appearance PBRAppearance {
            baseColor 0 0.666667 1
            metalness 0
          }
          geometry Box {
            size 0.01 0.01 0.01
          }
        }
      ]
      name "ds_right"
    }
    DEF BODY Shape {
      appearance PBRAppearance {
        baseColor 1 0 0
        roughness 0.5
        metalness 0
      }
      geometry Box {
        size 0.1 0.05 0.2
      }
    }
    HingeJoint {
      jointParameters HingeJointParameters {
        anchor 0.06 0 0.05
      }
      device [
        RotationalMotor {
          name "wheel1"
        }
      ]
      endPoint DEF WHEEL1 Solid {
        translation 0.06 0 0.05
        rotation -3.9252239376397583e-16 -1.5700895750559034e-16 1 1.5707999999999998
        children [
          DEF WHEEL1 Shape {
            appearance PBRAppearance {
              baseColor 0 1 0
              roughness 0.5
              metalness 0
            }
            geometry Cylinder {
              height 0.02
              radius 0.04
            }
          }
        ]
        name "solid(1)"
        boundingObject USE WHEEL1
        physics DEF WHEEL_PH Physics {
        }
      }
    }
    HingeJoint {
      jointParameters HingeJointParameters {
        anchor -0.06 0 0.05
      }
      device [
        RotationalMotor {
          name "wheel2"
        }
      ]
      endPoint Solid {
        translation -0.06 0 0.05
        rotation 5.102791118931688e-16 2.355134362583855e-16 1 1.5707999999999995
        children [
          DEF WHEEL2 Shape {
            appearance PBRAppearance {
              baseColor 0 1 0
              roughness 0.5
              metalness 0
            }
            geometry Cylinder {
              height 0.02
              radius 0.04
            }
          }
        ]
        boundingObject USE WHEEL2
        physics USE WHEEL_PH
      }
    }
    HingeJoint {
      jointParameters HingeJointParameters {
        anchor 0.06 0 -0.05
      }
      device [
        RotationalMotor {
          name "wheel3"
        }
      ]
      endPoint Solid {
        translation 0.06 0 -0.05
        rotation 1.5700895750559031e-16 0 1 1.5707999999999998
        children [
          DEF WHEEL3 Shape {
            appearance PBRAppearance {
              baseColor 0 1 0
              roughness 0.5
              metalness 0
            }
            geometry Cylinder {
              height 0.02
              radius 0.04
            }
          }
        ]
        name "solid(2)"
        boundingObject USE WHEEL3
        physics USE WHEEL_PH
      }
    }
    HingeJoint {
      jointParameters HingeJointParameters {
        anchor -0.06 0 -0.05
      }
      device [
        RotationalMotor {
          name "wheel4"
        }
      ]
      endPoint Solid {
        translation -0.06 0 -0.05
        rotation -3.532701543875782e-16 1.1775671812919274e-16 1 1.5708
        children [
          DEF WHEEL4 Shape {
            appearance PBRAppearance {
              baseColor 0 1 0
              roughness 0.5
              metalness 0
            }
            geometry Cylinder {
              height 0.02
              radius 0.04
            }
          }
        ]
        name "solid(3)"
        boundingObject USE WHEEL4
        physics USE WHEEL_PH
      }
    }
  ]
  boundingObject USE BODY
  physics Physics {
  }
  controller "Robo_de_4_Rodas"
}
